<?xml version="1.0" ?>
<robot name="partnet_235c8ef29ef5fc5bafd49046c1129780">
	<link name="base"/>
	<link name="link_0">
		<visual name="caster_yoke-28">
			<origin xyz="0.011963000000000001 0 -0.6146955000000001"/>
			<geometry>
				<mesh filename="textured_objs/original-15.obj"/>
			</geometry>
		</visual>
		<collision>
			<origin xyz="0.011963000000000001 0 -0.6146955000000001"/>
			<geometry>
				<mesh filename="textured_objs/original-15.obj"/>
			</geometry>
		</collision>
	</link>
	<joint name="joint_0" type="continuous">
		<origin xyz="-0.011963000000000001 0 0.6146955000000001"/>
		<axis xyz="0 1 0"/>
		<child link="link_0"/>
		<parent link="link_11"/>
	</joint>
	<link name="link_1">
		<visual name="wheel-29">
			<origin xyz="0 0.7640865 -0.5941266709400181"/>
			<geometry>
				<mesh filename="textured_objs/original-29.obj"/>
			</geometry>
		</visual>
		<collision>
			<origin xyz="0 0.7640865 -0.5941266709400181"/>
			<geometry>
				<mesh filename="textured_objs/original-29.obj"/>
			</geometry>
		</collision>
	</link>
	<joint name="joint_1" type="continuous">
		<origin xyz="0.011963000000000001 -0.7640865 -0.02056882905998192"/>
		<axis xyz="1 0 0"/>
		<child link="link_1"/>
		<parent link="link_0"/>
	</joint>
	<link name="link_2">
		<visual name="caster_yoke-26">
			<origin xyz="-0.5362257999995023 0 -0.21646960000149323"/>
			<geometry>
				<mesh filename="textured_objs/original-14.obj"/>
			</geometry>
		</visual>
		<collision>
			<origin xyz="-0.5362257999995023 0 -0.21646960000149323"/>
			<geometry>
				<mesh filename="textured_objs/original-14.obj"/>
			</geometry>
		</collision>
	</link>
	<joint name="joint_2" type="continuous">
		<origin xyz="0.5362257999995023 0 0.21646960000149323"/>
		<axis xyz="0 1 0"/>
		<child link="link_2"/>
		<parent link="link_11"/>
	</joint>
	<link name="link_3">
		<visual name="wheel-27">
			<origin xyz="-0.5237185459317936 0.764086 -0.19043104580995815"/>
			<geometry>
				<mesh filename="textured_objs/original-28.obj"/>
			</geometry>
		</visual>
		<collision>
			<origin xyz="-0.5237185459317936 0.764086 -0.19043104580995815"/>
			<geometry>
				<mesh filename="textured_objs/original-28.obj"/>
			</geometry>
		</collision>
	</link>
	<joint name="joint_3" type="continuous">
		<origin xyz="-0.012507254067708695 -0.764086 -0.026038554191535085"/>
		<axis xyz="0.34172394267532935 0 -0.939800376145077"/>
		<child link="link_3"/>
		<parent link="link_2"/>
	</joint>
	<link name="link_4">
		<visual name="caster_yoke-24">
			<origin xyz="-0.3267085 0 0.4278675"/>
			<geometry>
				<mesh filename="textured_objs/original-13.obj"/>
			</geometry>
		</visual>
		<collision>
			<origin xyz="-0.3267085 0 0.4278675"/>
			<geometry>
				<mesh filename="textured_objs/original-13.obj"/>
			</geometry>
		</collision>
	</link>
	<joint name="joint_4" type="continuous">
		<origin xyz="0.3267085 0 -0.4278675"/>
		<axis xyz="0 1 0"/>
		<child link="link_4"/>
		<parent link="link_11"/>
	</joint>
	<link name="link_5">
		<visual name="wheel-25">
			<origin xyz="-0.3042891459191006 0.7640865 0.41838766191728793"/>
			<geometry>
				<mesh filename="textured_objs/original-27.obj"/>
			</geometry>
		</visual>
		<collision>
			<origin xyz="-0.3042891459191006 0.7640865 0.41838766191728793"/>
			<geometry>
				<mesh filename="textured_objs/original-27.obj"/>
			</geometry>
		</collision>
	</link>
	<joint name="joint_5" type="continuous">
		<origin xyz="-0.0224193540808994 -0.7640865 0.009479838082712078"/>
		<axis xyz="0.8087294380934793 0 0.588180836104854"/>
		<child link="link_5"/>
		<parent link="link_4"/>
	</joint>
	<link name="link_6">
		<visual name="caster_yoke-22">
			<origin xyz="0.3506345 0 0.4278675"/>
			<geometry>
				<mesh filename="textured_objs/original-16.obj"/>
			</geometry>
		</visual>
		<collision>
			<origin xyz="0.3506345 0 0.4278675"/>
			<geometry>
				<mesh filename="textured_objs/original-16.obj"/>
			</geometry>
		</collision>
	</link>
	<joint name="joint_6" type="continuous">
		<origin xyz="-0.3506345 0 -0.4278675"/>
		<axis xyz="0 1 0"/>
		<child link="link_6"/>
		<parent link="link_11"/>
	</joint>
	<link name="link_7">
		<visual name="wheel-23">
			<origin xyz="0.30431093534904385 0.764086 0.4347169488297647"/>
			<geometry>
				<mesh filename="textured_objs/original-30.obj"/>
			</geometry>
		</visual>
		<collision>
			<origin xyz="0.30431093534904385 0.764086 0.4347169488297647"/>
			<geometry>
				<mesh filename="textured_objs/original-30.obj"/>
			</geometry>
		</collision>
	</link>
	<joint name="joint_7" type="continuous">
		<origin xyz="0.04632356465095616 -0.764086 -0.006849448829764682"/>
		<axis xyz="0.8192238749305725 0 -0.573473837889522"/>
		<child link="link_7"/>
		<parent link="link_6"/>
	</joint>
	<link name="link_8">
		<visual name="caster_yoke-20">
			<origin xyz="0.5601515 0 -0.2164695"/>
			<geometry>
				<mesh filename="textured_objs/original-17.obj"/>
			</geometry>
		</visual>
		<collision>
			<origin xyz="0.5601515 0 -0.2164695"/>
			<geometry>
				<mesh filename="textured_objs/original-17.obj"/>
			</geometry>
		</collision>
	</link>
	<joint name="joint_8" type="continuous">
		<origin xyz="-0.5601515 0 0.2164695"/>
		<axis xyz="0 1 0"/>
		<child link="link_8"/>
		<parent link="link_11"/>
	</joint>
	<link name="link_9">
		<visual name="wheel-21">
			<origin xyz="0.549526755481785 0.764086 -0.18316140654664578"/>
			<geometry>
				<mesh filename="textured_objs/original-31.obj"/>
			</geometry>
		</visual>
		<collision>
			<origin xyz="0.549526755481785 0.764086 -0.18316140654664578"/>
			<geometry>
				<mesh filename="textured_objs/original-31.obj"/>
			</geometry>
		</collision>
	</link>
	<joint name="joint_9" type="continuous">
		<origin xyz="0.010624744518215046 -0.764086 -0.033308093453354226"/>
		<axis xyz="-0.31620573068897784 0 -0.948690642875458"/>
		<child link="link_9"/>
		<parent link="link_8"/>
	</joint>
	<link name="link_10">
		<visual name="back_support-53">
			<origin xyz="0.011962500000000001 0 -0.0385235"/>
			<geometry>
				<mesh filename="textured_objs/original-4.obj"/>
			</geometry>
		</visual>
		<visual name="back_hard_surface-58">
			<origin xyz="0.011962500000000001 0 -0.0385235"/>
			<geometry>
				<mesh filename="textured_objs/new-10.obj"/>
			</geometry>
		</visual>
		<visual name="back_frame_vertical_bar-56">
			<origin xyz="0.011962500000000001 0 -0.0385235"/>
			<geometry>
				<mesh filename="textured_objs/new-6.obj"/>
			</geometry>
		</visual>
		<visual name="back_frame_vertical_bar-57">
			<origin xyz="0.011962500000000001 0 -0.0385235"/>
			<geometry>
				<mesh filename="textured_objs/new-8.obj"/>
			</geometry>
		</visual>
		<visual name="arm_holistic_frame-48">
			<origin xyz="0.011962500000000001 0 -0.0385235"/>
			<geometry>
				<mesh filename="textured_objs/original-2.obj"/>
			</geometry>
		</visual>
		<visual name="arm_connector-49">
			<origin xyz="0.011962500000000001 0 -0.0385235"/>
			<geometry>
				<mesh filename="textured_objs/original-22.obj"/>
			</geometry>
		</visual>
		<visual name="arm_connector-50">
			<origin xyz="0.011962500000000001 0 -0.0385235"/>
			<geometry>
				<mesh filename="textured_objs/original-3.obj"/>
			</geometry>
		</visual>
		<visual name="arm_connector-51">
			<origin xyz="0.011962500000000001 0 -0.0385235"/>
			<geometry>
				<mesh filename="textured_objs/original-24.obj"/>
			</geometry>
		</visual>
		<visual name="arm_holistic_frame-44">
			<origin xyz="0.011962500000000001 0 -0.0385235"/>
			<geometry>
				<mesh filename="textured_objs/original-7.obj"/>
			</geometry>
		</visual>
		<visual name="arm_connector-45">
			<origin xyz="0.011962500000000001 0 -0.0385235"/>
			<geometry>
				<mesh filename="textured_objs/original-8.obj"/>
			</geometry>
		</visual>
		<visual name="arm_connector-46">
			<origin xyz="0.011962500000000001 0 -0.0385235"/>
			<geometry>
				<mesh filename="textured_objs/original-23.obj"/>
			</geometry>
		</visual>
		<visual name="arm_connector-47">
			<origin xyz="0.011962500000000001 0 -0.0385235"/>
			<geometry>
				<mesh filename="textured_objs/original-25.obj"/>
			</geometry>
		</visual>
		<visual name="seat_support-31">
			<origin xyz="0.011962500000000001 0 -0.0385235"/>
			<geometry>
				<mesh filename="textured_objs/original-19.obj"/>
			</geometry>
		</visual>
		<visual name="seat_support-37">
			<origin xyz="0.011962500000000001 0 -0.0385235"/>
			<geometry>
				<mesh filename="textured_objs/original-20.obj"/>
			</geometry>
		</visual>
		<visual name="seat_support-39">
			<origin xyz="0.011962500000000001 0 -0.0385235"/>
			<geometry>
				<mesh filename="textured_objs/original-18.obj"/>
			</geometry>
		</visual>
		<visual name="seat_hard_surface-43">
			<origin xyz="0.011962500000000001 0 -0.0385235"/>
			<geometry>
				<mesh filename="textured_objs/new-9.obj"/>
			</geometry>
		</visual>
		<visual name="seat_support-41">
			<origin xyz="0.011962500000000001 0 -0.0385235"/>
			<geometry>
				<mesh filename="textured_objs/new-7.obj"/>
			</geometry>
		</visual>
		<visual name="seat_support-42">
			<origin xyz="0.011962500000000001 0 -0.0385235"/>
			<geometry>
				<mesh filename="textured_objs/new-5.obj"/>
			</geometry>
		</visual>
		<visual name="central_support-7">
			<origin xyz="0.011962500000000001 0 -0.0385235"/>
			<geometry>
				<mesh filename="textured_objs/original-10.obj"/>
			</geometry>
		</visual>
		<visual name="central_support-32">
			<origin xyz="0.011962500000000001 0 -0.0385235"/>
			<geometry>
				<mesh filename="textured_objs/original-21.obj"/>
			</geometry>
		</visual>
		<collision>
			<origin xyz="0.011962500000000001 0 -0.0385235"/>
			<geometry>
				<mesh filename="textured_objs/original-4.obj"/>
			</geometry>
		</collision>
		<collision>
			<origin xyz="0.011962500000000001 0 -0.0385235"/>
			<geometry>
				<mesh filename="textured_objs/new-10.obj"/>
			</geometry>
		</collision>
		<collision>
			<origin xyz="0.011962500000000001 0 -0.0385235"/>
			<geometry>
				<mesh filename="textured_objs/new-6.obj"/>
			</geometry>
		</collision>
		<collision>
			<origin xyz="0.011962500000000001 0 -0.0385235"/>
			<geometry>
				<mesh filename="textured_objs/new-8.obj"/>
			</geometry>
		</collision>
		<collision>
			<origin xyz="0.011962500000000001 0 -0.0385235"/>
			<geometry>
				<mesh filename="textured_objs/original-2.obj"/>
			</geometry>
		</collision>
		<collision>
			<origin xyz="0.011962500000000001 0 -0.0385235"/>
			<geometry>
				<mesh filename="textured_objs/original-22.obj"/>
			</geometry>
		</collision>
		<collision>
			<origin xyz="0.011962500000000001 0 -0.0385235"/>
			<geometry>
				<mesh filename="textured_objs/original-3.obj"/>
			</geometry>
		</collision>
		<collision>
			<origin xyz="0.011962500000000001 0 -0.0385235"/>
			<geometry>
				<mesh filename="textured_objs/original-24.obj"/>
			</geometry>
		</collision>
		<collision>
			<origin xyz="0.011962500000000001 0 -0.0385235"/>
			<geometry>
				<mesh filename="textured_objs/original-7.obj"/>
			</geometry>
		</collision>
		<collision>
			<origin xyz="0.011962500000000001 0 -0.0385235"/>
			<geometry>
				<mesh filename="textured_objs/original-8.obj"/>
			</geometry>
		</collision>
		<collision>
			<origin xyz="0.011962500000000001 0 -0.0385235"/>
			<geometry>
				<mesh filename="textured_objs/original-23.obj"/>
			</geometry>
		</collision>
		<collision>
			<origin xyz="0.011962500000000001 0 -0.0385235"/>
			<geometry>
				<mesh filename="textured_objs/original-25.obj"/>
			</geometry>
		</collision>
		<collision>
			<origin xyz="0.011962500000000001 0 -0.0385235"/>
			<geometry>
				<mesh filename="textured_objs/original-19.obj"/>
			</geometry>
		</collision>
		<collision>
			<origin xyz="0.011962500000000001 0 -0.0385235"/>
			<geometry>
				<mesh filename="textured_objs/original-20.obj"/>
			</geometry>
		</collision>
		<collision>
			<origin xyz="0.011962500000000001 0 -0.0385235"/>
			<geometry>
				<mesh filename="textured_objs/original-18.obj"/>
			</geometry>
		</collision>
		<collision>
			<origin xyz="0.011962500000000001 0 -0.0385235"/>
			<geometry>
				<mesh filename="textured_objs/new-9.obj"/>
			</geometry>
		</collision>
		<collision>
			<origin xyz="0.011962500000000001 0 -0.0385235"/>
			<geometry>
				<mesh filename="textured_objs/new-7.obj"/>
			</geometry>
		</collision>
		<collision>
			<origin xyz="0.011962500000000001 0 -0.0385235"/>
			<geometry>
				<mesh filename="textured_objs/new-5.obj"/>
			</geometry>
		</collision>
		<collision>
			<origin xyz="0.011962500000000001 0 -0.0385235"/>
			<geometry>
				<mesh filename="textured_objs/original-10.obj"/>
			</geometry>
		</collision>
		<collision>
			<origin xyz="0.011962500000000001 0 -0.0385235"/>
			<geometry>
				<mesh filename="textured_objs/original-21.obj"/>
			</geometry>
		</collision>
	</link>
	<joint name="joint_10" type="continuous">
		<origin xyz="0.0 0 0.0"/>
		<axis xyz="0 1 0"/>
		<child link="link_10"/>
		<parent link="link_10_helper"/>
	</joint>
	<link name="link_11">
		<visual name="central_support-8">
			<origin xyz="0 0 0"/>
			<geometry>
				<mesh filename="textured_objs/original-9.obj"/>
			</geometry>
		</visual>
		<visual name="leg-10">
			<origin xyz="0 0 0"/>
			<geometry>
				<mesh filename="textured_objs/new-2.obj"/>
			</geometry>
		</visual>
		<visual name="leg-11">
			<origin xyz="0 0 0"/>
			<geometry>
				<mesh filename="textured_objs/new-4.obj"/>
			</geometry>
		</visual>
		<visual name="leg-12">
			<origin xyz="0 0 0"/>
			<geometry>
				<mesh filename="textured_objs/new-3.obj"/>
			</geometry>
		</visual>
		<visual name="leg-13">
			<origin xyz="0 0 0"/>
			<geometry>
				<mesh filename="textured_objs/new-0.obj"/>
			</geometry>
		</visual>
		<visual name="leg-14">
			<origin xyz="0 0 0"/>
			<geometry>
				<mesh filename="textured_objs/new-1.obj"/>
			</geometry>
		</visual>
		<collision>
			<origin xyz="0 0 0"/>
			<geometry>
				<mesh filename="textured_objs/original-9.obj"/>
			</geometry>
		</collision>
		<collision>
			<origin xyz="0 0 0"/>
			<geometry>
				<mesh filename="textured_objs/new-2.obj"/>
			</geometry>
		</collision>
		<collision>
			<origin xyz="0 0 0"/>
			<geometry>
				<mesh filename="textured_objs/new-4.obj"/>
			</geometry>
		</collision>
		<collision>
			<origin xyz="0 0 0"/>
			<geometry>
				<mesh filename="textured_objs/new-3.obj"/>
			</geometry>
		</collision>
		<collision>
			<origin xyz="0 0 0"/>
			<geometry>
				<mesh filename="textured_objs/new-0.obj"/>
			</geometry>
		</collision>
		<collision>
			<origin xyz="0 0 0"/>
			<geometry>
				<mesh filename="textured_objs/new-1.obj"/>
			</geometry>
		</collision>
	</link>
	<joint name="joint_11" type="fixed">
		<origin rpy="1.570796326794897 0 -1.570796326794897" xyz="0 0 0"/>
		<child link="link_11"/>
		<parent link="base"/>
	</joint>
	<link name="link_10_helper"/>
	<joint name="joint_12" type="prismatic">
		<origin xyz="-0.011962500000000001 0 0.0385235"/>
		<axis xyz="0 -1 0"/>
		<child link="link_10_helper"/>
		<parent link="link_11"/>
		<limit lower="0" upper="0.1"/>
	</joint>
</robot>
